Workbook

Sheet INGRESOS
A1: FECHA | B1: DIA | C1: MES | D1: ANIO | E1: TIPO_DIA | F1: NUM_SEM | G1: QNA | H1: MONTO | I1: BANCO | J1: CONCEPTO | K1: COMENTARIOS | L1: SALDO ACUM | M1: RECAT | N1: AGRUPACION | O1: INDICE
A2: 45507 | B2: =DAY(A2) -> 3 | C2: =MONTH(A2) -> 8 | D2: =YEAR(A2) -> 2024 | E2: =WEEKDAY(A2,2) -> 6 | F2: =WEEKNUM(A2,2) - WEEKNUM(DATE(YEAR(A2),MONTH(A2),1),2) + 1 -> 1 | H2: 277 | I2: BBVA | M2: NO DATO | N2: NO DATO | O2: NO DATO
A3: 45519 | B3: =DAY(A3) -> 15 | C3: =MONTH(A3) -> 8 | D3: =YEAR(A3) -> 2024 | E3: =WEEKDAY(A3,2) -> 4 | F3: =WEEKNUM(A3,2) - WEEKNUM(DATE(YEAR(A3),MONTH(A3),1),2) + 1 -> 3 | G3: 1 | H3: 729.22 | I3: BBVA | M3: NO DATO | N3: NO DATO | O3: NO DATO
A4: 45522 | B4: =DAY(A4) -> 18 | C4: =MONTH(A4) -> 8 | D4: =YEAR(A4) -> 2024 | E4: =WEEKDAY(A4,2) -> 7 | F4: =WEEKNUM(A4,2) - WEEKNUM(DATE(YEAR(A4),MONTH(A4),1),2) + 1 -> 3 | H4: 1856.11 | I4: BBVA | M4: NO DATO | N4: NO DATO | O4: NO DATO
A5: 45524 | B5: =DAY(A5) -> 20 | C5: =MONTH(A5) -> 8 | D5: =YEAR(A5) -> 2024 | E5: =WEEKDAY(A5,2) -> 2 | F5: =WEEKNUM(A5,2) - WEEKNUM(DATE(YEAR(A5),MONTH(A5),1),2) + 1 -> 4 | H5: 1043.51 | I5: BBVA | M5: NO DATO | N5: NO DATO | O5: NO DATO
A6: 45529 | B6: =DAY(A6) -> 25 | C6: =MONTH(A6) -> 8 | D6: =YEAR(A6) -> 2024 | E6: =WEEKDAY(A6,2) -> 7 | F6: =WEEKNUM(A6,2) - WEEKNUM(DATE(YEAR(A6),MONTH(A6),1),2) + 1 -> 4 | H6: 575.67 | I6: BBVA | M6: NO DATO | N6: NO DATO | O6: NO DATO
A7: 44968 | B7: =DAY(A7) -> 11 | C7: =MONTH(A7) -> 2 | D7: =YEAR(A7) -> 2023 | E7: =WEEKDAY(A7,2) -> 6 | F7: =WEEKNUM(A7,2) - WEEKNUM(DATE(YEAR(A7),MONTH(A7),1),2) + 1 -> 2 | H7: 1815 | I7: BBVA | J7: DONATIVO | M7: =VLOOKUP(J7,RECATALOGANDO!A:C,2,0) -> DONATIVO | N7: =VLOOKUP(M7,RECATALOGANDO!B:C,2,0) -> DONATIVO | O7: NO ES INGRESO
A8: 44968 | B8: =DAY(A8) -> 11 | C8: =MONTH(A8) -> 2 | D8: =YEAR(A8) -> 2023 | E8: =WEEKDAY(A8,2) -> 6 | F8: =WEEKNUM(A8,2) - WEEKNUM(DATE(YEAR(A8),MONTH(A8),1),2) + 1 -> 2 | H8: 1815 | I8: BBVA | J8: DONATIVO | M8: =VLOOKUP(J8,RECATALOGANDO!A:C,2,0) -> DONATIVO | N8: =VLOOKUP(M8,RECATALOGANDO!B:C,2,0) -> DONATIVO | O8: NO ES INGRESO
A9: 45118 | B9: =DAY(A9) -> 11 | C9: =MONTH(A9) -> 7 | D9: =YEAR(A9) -> 2023 | E9: =WEEKDAY(A9,2) -> 2 | F9: =WEEKNUM(A9,2) - WEEKNUM(DATE(YEAR(A9),MONTH(A9),1),2) + 1 -> 3 | H9: 55900 | I9: BBVA | J9: PRESTAMO BANCARIO | M9: =VLOOKUP(J9,RECATALOGANDO!A:C,2,0) -> PRESTAMO BANCARIO | N9: =VLOOKUP(M9,RECATALOGANDO!B:C,2,0) -> PRESTAMO | O9: NO ES INGRESO
A10: 45173 | B10: =DAY(A10) -> 4 | C10: =MONTH(A10) -> 9 | D10: =YEAR(A10) -> 2023 | E10: =WEEKDAY(A10,2) -> 1 | F10: =WEEKNUM(A10,2) - WEEKNUM(DATE(YEAR(A10),MONTH(A10),1),2) + 1 -> 2 | H10: 26571 | I10: BANAMEX | J10: DEPÓSITO EQUIVOCADO Y DEVUELTO | M10: =VLOOKUP(J10,RECATALOGANDO!A:C,2,0) -> REEMBOLSO | N10: =VLOOKUP(M10,RECATALOGANDO!B:C,2,0) -> DINERO DEVUELTO A ORIGEN | O10: NO ES INGRESO
A11: 45181 | B11: =DAY(A11) -> 12 | C11: =MONTH(A11) -> 9 | D11: =YEAR(A11) -> 2023 | E11: =WEEKDAY(A11,2) -> 2 | F11: =WEEKNUM(A11,2) - WEEKNUM(DATE(YEAR(A11),MONTH(A11),1),2) + 1 -> 3 | H11: 80000 | I11: BBVA | J11: DEPÓSITO PRESTAMO | M11: =VLOOKUP(J11,RECATALOGANDO!A:C,2,0) -> DEPÓSITO PRESTAMO | N11: =VLOOKUP(M11,RECATALOGANDO!B:C,2,0) -> PRESTAMO | O11: NO ES INGRESO
A12: 45215 | B12: =DAY(A12) -> 16 | C12: =MONTH(A12) -> 10 | D12: =YEAR(A12) -> 2023 | E12: =WEEKDAY(A12,2) -> 1 | F12: =WEEKNUM(A12,2) - WEEKNUM(DATE(YEAR(A12),MONTH(A12),1),2) + 1 -> 4 | H12: 200 | I12: BANAMEX | J12: REEMBOLSO | M12: =VLOOKUP(J12,RECATALOGANDO!A:C,2,0) -> REEMBOLSO | N12: =VLOOKUP(M12,RECATALOGANDO!B:C,2,0) -> DINERO DEVUELTO A ORIGEN | O12: NO ES INGRESO
A13: 45282 | B13: =DAY(A13) -> 22 | C13: =MONTH(A13) -> 12 | D13: =YEAR(A13) -> 2023 | E13: =WEEKDAY(A13,2) -> 5 | F13: =WEEKNUM(A13,2) - WEEKNUM(DATE(YEAR(A13),MONTH(A13),1),2) + 1 -> 4 | H13: 2895 | I13: BBVA | J13: REEMBOLSO POR DEPOSITO EQUIVOCADO | M13: =VLOOKUP(J13,RECATALOGANDO!A:C,2,0) -> REEMBOLSO | N13: =VLOOKUP(M13,RECATALOGANDO!B:C,2,0) -> DINERO DEVUELTO A ORIGEN | O13: NO ES INGRESO
A14: 45365 | B14: =DAY(A14) -> 14 | C14: =MONTH(A14) -> 3 | D14: =YEAR(A14) -> 2024 | E14: =WEEKDAY(A14,2) -> 4 | F14: =WEEKNUM(A14,2) - WEEKNUM(DATE(YEAR(A14),MONTH(A14),1),2) + 1 -> 3 | H14: 3500 | I14: BBVA | J14: REEMBOLSO | M14: =VLOOKUP(J14,RECATALOGANDO!A:C,2,0) -> REEMBOLSO | N14: =VLOOKUP(M14,RECATALOGANDO!B:C,2,0) -> DINERO DEVUELTO A ORIGEN | O14: NO ES INGRESO
A15: 45366 | B15: =DAY(A15) -> 15 | C15: =MONTH(A15) -> 3 | D15: =YEAR(A15) -> 2024 | E15: =WEEKDAY(A15,2) -> 5 | F15: =WEEKNUM(A15,2) - WEEKNUM(DATE(YEAR(A15),MONTH(A15),1),2) + 1 -> 3 | G15: 1 | H15: 140 | I15: BANAMEX | J15: REEMBOLSO | M15: =VLOOKUP(J15,RECATALOGANDO!A:C,2,0) -> REEMBOLSO | N15: =VLOOKUP(M15,RECATALOGANDO!B:C,2,0) -> DINERO DEVUELTO A ORIGEN | O15: NO ES INGRESO
A16: 45527 | B16: =DAY(A16) -> 23 | C16: =MONTH(A16) -> 8 | D16: =YEAR(A16) -> 2024 | E16: =WEEKDAY(A16,2) -> 5 | F16: =WEEKNUM(A16,2) - WEEKNUM(DATE(YEAR(A16),MONTH(A16),1),2) + 1 -> 4 | H16: 5000 | I16: BANAMEX | J16: PENSIÓN ALIMENTICIA | M16: =VLOOKUP(J16,RECATALOGANDO!A:C,2,0) -> PENSION ALIMENTICIA | N16: =VLOOKUP(M16,RECATALOGANDO!B:C,2,0) -> PENSION | O16: NO ES INGRESO
A17: 45587 | B17: =DAY(A17) -> 22 | C17: =MONTH(A17) -> 10 | D17: =YEAR(A17) -> 2024 | E17: =WEEKDAY(A17,2) -> 2 | F17: =WEEKNUM(A17,2) - WEEKNUM(DATE(YEAR(A17),MONTH(A17),1),2) + 1 -> 4 | H17: 7800 | I17: BANAMEX | J17: DEPOSITO EQUIVOCADO QUE FUE REEMBOLSADO | M17: =VLOOKUP(J17,RECATALOGANDO!A:C,2,0) -> REEMBOLSO | N17: =VLOOKUP(M17,RECATALOGANDO!B:C,2,0) -> DINERO DEVUELTO A ORIGEN | O17: NO ES INGRESO
A18: 45589 | B18: =DAY(A18) -> 24 | C18: =MONTH(A18) -> 10 | D18: =YEAR(A18) -> 2024 | E18: =WEEKDAY(A18,2) -> 4 | F18: =WEEKNUM(A18,2) - WEEKNUM(DATE(YEAR(A18),MONTH(A18),1),2) + 1 -> 4 | H18: 1340 | I18: BANAMEX | J18: DEVOLUCIÓN SPEI | M18: =VLOOKUP(J18,RECATALOGANDO!A:C,2,0) -> REEMBOLSO | N18: =VLOOKUP(M18,RECATALOGANDO!B:C,2,0) -> DINERO DEVUELTO A ORIGEN | O18: NO ES INGRESO
A19: 45602 | B19: =DAY(A19) -> 6 | C19: =MONTH(A19) -> 11 | D19: =YEAR(A19) -> 2024 | E19: =WEEKDAY(A19,2) -> 3 | F19: =WEEKNUM(A19,2) - WEEKNUM(DATE(YEAR(A19),MONTH(A19),1),2) + 1 -> 2 | H19: 226309.64 | I19: BBVA | J19: DEPOSITO PENSION ALIMENTICIA | M19: =VLOOKUP(J19,RECATALOGANDO!A:C,2,0) -> PENSION ALIMENTICIA | N19: =VLOOKUP(M19,RECATALOGANDO!B:C,2,0) -> PENSION | O19: NO ES INGRESO
A20: 45693 | B20: =DAY(A20) -> 5 | C20: =MONTH(A20) -> 2 | D20: =YEAR(A20) -> 2025 | E20: =WEEKDAY(A20,2) -> 3 | F20: =WEEKNUM(A20,2) - WEEKNUM(DATE(YEAR(A20),MONTH(A20),1),2) + 1 -> 2 | H20: 676.46 | I20: BANAMEX | J20: ABONO POR REEMBOLSO POR CARGO NO RECONOCIDO | M20: =VLOOKUP(J20,RECATALOGANDO!A:C,2,0) -> REEMBOLSO | N20: =VLOOKUP(M20,RECATALOGANDO!B:C,2,0) -> DINERO DEVUELTO A ORIGEN | O20: NO ES INGRESO
A21: 45695 | B21: =DAY(A21) -> 7 | C21: =MONTH(A21) -> 2 | D21: =YEAR(A21) -> 2025 | E21: =WEEKDAY(A21,2) -> 5 | F21: =WEEKNUM(A21,2) - WEEKNUM(DATE(YEAR(A21),MONTH(A21),1),2) + 1 -> 2 | H21: 676.46 | I21: BANAMEX | J21: ABONO POR REEMBOLSO POR CARGO NO RECONOCIDO | M21: =VLOOKUP(J21,RECATALOGANDO!A:C,2,0) -> REEMBOLSO | N21: =VLOOKUP(M21,RECATALOGANDO!B:C,2,0) -> DINERO DEVUELTO A ORIGEN | O21: NO ES INGRESO
A22: 45698 | B22: =DAY(A22) -> 10 | C22: =MONTH(A22) -> 2 | D22: =YEAR(A22) -> 2025 | E22: =WEEKDAY(A22,2) -> 1 | F22: =WEEKNUM(A22,2) - WEEKNUM(DATE(YEAR(A22),MONTH(A22),1),2) + 1 -> 3 | H22: 676.46 | I22: BANAMEX | J22: ABONO POR REEMBOLSO POR CARGO NO RECONOCIDO | M22: =VLOOKUP(J22,RECATALOGANDO!A:C,2,0) -> REEMBOLSO | N22: =VLOOKUP(M22,RECATALOGANDO!B:C,2,0) -> DINERO DEVUELTO A ORIGEN | O22: NO ES INGRESO
A23: 44930 | B23: =DAY(A23) -> 4 | C23: =MONTH(A23) -> 1 | D23: =YEAR(A23) -> 2023 | E23: =WEEKDAY(A23,2) -> 3 | F23: =WEEKNUM(A23,2) - WEEKNUM(DATE(YEAR(A23),MONTH(A23),1),2) + 1 -> 2 | H23: 1000 | I23: BANAMEX | J23: TRANFERENCIA ENTRE CUENTAS | M23: =VLOOKUP(J23,RECATALOGANDO!A:C,2,0) -> TRANSFERENCIA ENTRE CUENTAS | N23: =VLOOKUP(M23,RECATALOGANDO!B:C,2,0) -> TRANSFERENCIAS | O23: TRANSFERENCIAS
A24: 44941 | B24: =DAY(A24) -> 15 | C24: =MONTH(A24) -> 1 | D24: =YEAR(A24) -> 2023 | E24: =WEEKDAY(A24,2) -> 7 | F24: =WEEKNUM(A24,2) - WEEKNUM(DATE(YEAR(A24),MONTH(A24),1),2) + 1 -> 3 | H24: 200 | I24: BBVA | J24: TRANFERENCIA ENTRE CUENTAS | M24: =VLOOKUP(J24,RECATALOGANDO!A:C,2,0) -> TRANSFERENCIA ENTRE CUENTAS | N24: =VLOOKUP(M24,RECATALOGANDO!B:C,2,0) -> TRANSFERENCIAS | O24: TRANSFERENCIAS
A25: 44956 | B25: =DAY(A25) -> 30 | C25: =MONTH(A25) -> 1 | D25: =YEAR(A25) -> 2023 | E25: =WEEKDAY(A25,2) -> 1 | F25: =WEEKNUM(A25,2) - WEEKNUM(DATE(YEAR(A25),MONTH(A25),1),2) + 1 -> 6 | G25: 2 | H25: 700 | I25: BBVA | J25: TRANSFERENCIA ENTRE CUENTAS | M25: =VLOOKUP(J25,RECATALOGANDO!A:C,2,0) -> TRANSFERENCIA ENTRE CUENTAS | N25: =VLOOKUP(M25,RECATALOGANDO!B:C,2,0) -> TRANSFERENCIAS | O25: TRANSFERENCIAS
A26: 44956 | B26: =DAY(A26) -> 30 | C26: =MONTH(A26) -> 1 | D26: =YEAR(A26) -> 2023 | E26: =WEEKDAY(A26,2) -> 1 | F26: =WEEKNUM(A26,2) - WEEKNUM(DATE(YEAR(A26),MONTH(A26),1),2) + 1 -> 6 | G26: 2 | H26: 700 | I26: BBVA | J26: TRANSFERENCIA ENTRE CUENTAS | M26: =VLOOKUP(J26,RECATALOGANDO!A:C,2,0) -> TRANSFERENCIA ENTRE CUENTAS | N26: =VLOOKUP(M26,RECATALOGANDO!B:C,2,0) -> TRANSFERENCIAS | O26: TRANSFERENCIAS
A27: 44958 | B27: =DAY(A27) -> 1 | C27: =MONTH(A27) -> 2 | D27: =YEAR(A27) -> 2023 | E27: =WEEKDAY(A27,2) -> 3 | F27: =WEEKNUM(A27,2) - WEEKNUM(DATE(YEAR(A27),MONTH(A27),1),2) + 1 -> 1 | H27: 1000 | I27: BANAMEX | J27: TRANSFERENCIA ENTRE CUENTAS | M27: =VLOOKUP(J27,RECATALOGANDO!A:C,2,0) -> TRANSFERENCIA ENTRE CUENTAS | N27: =VLOOKUP(M27,RECATALOGANDO!B:C,2,0) -> TRANSFERENCIAS | O27: TRANSFERENCIAS
A28: 44958 | B28: =DAY(A28) -> 1 | C28: =MONTH(A28) -> 2 | D28: =YEAR(A28) -> 2023 | E28: =WEEKDAY(A28,2) -> 3 | F28: =WEEKNUM(A28,2) - WEEKNUM(DATE(YEAR(A28),MONTH(A28),1),2) + 1 -> 1 | H28: 1000 | I28: BANAMEX | J28: TRANSFERENCIA ENTRE CUENTAS | M28: =VLOOKUP(J28,RECATALOGANDO!A:C,2,0) -> TRANSFERENCIA ENTRE CUENTAS | N28: =VLOOKUP(M28,RECATALOGANDO!B:C,2,0) -> TRANSFERENCIAS | O28: TRANSFERENCIAS
A29: 44965 | B29: =DAY(A29) -> 8 | C29: =MONTH(A29) -> 2 | D29: =YEAR(A29) -> 2023 | E29: =WEEKDAY(A29,2) -> 3 | F29: =WEEKNUM(A29,2) - WEEKNUM(DATE(YEAR(A29),MONTH(A29),1),2) + 1 -> 2 | H29: 500 | I29: BANAMEX | J29: TRANSFERENCIA ENTRE CUENTAS | M29: =VLOOKUP(J29,RECATALOGANDO!A:C,2,0) -> TRANSFERENCIA ENTRE CUENTAS | N29: =VLOOKUP(M29,RECATALOGANDO!B:C,2,0) -> TRANSFERENCIAS | O29: TRANSFERENCIAS
A30: 44965 | B30: =DAY(A30) -> 8 | C30: =MONTH(A30) -> 2 | D30: =YEAR(A30) -> 2023 | E30: =WEEKDAY(A30,2) -> 3 | F30: =WEEKNUM(A30,2) - WEEKNUM(DATE(YEAR(A30),MONTH(A30),1),2) + 1 -> 2 | H30: 500 | I30: BANAMEX | J30: TRANSFERENCIA ENTRE CUENTAS | M30: =VLOOKUP(J30,RECATALOGANDO!A:C,2,0) -> TRANSFERENCIA ENTRE CUENTAS | N30: =VLOOKUP(M30,RECATALOGANDO!B:C,2,0) -> TRANSFERENCIAS | O30: TRANSFERENCIAS
A31: 44970 | B31: =DAY(A31) -> 13 | C31: =MONTH(A31) -> 2 | D31: =YEAR(A31) -> 2023 | E31: =WEEKDAY(A31,2) -> 1 | F31: =WEEKNUM(A31,2) - WEEKNUM(DATE(YEAR(A31),MONTH(A31),1),2) + 1 -> 3 | H31: 1700 | I31: BANAMEX | J31: TRANSFERENCIA ENTRE CUENTAS | M31: =VLOOKUP(J31,RECATALOGANDO!A:C,2,0) -> TRANSFERENCIA ENTRE CUENTAS | N31: =VLOOKUP(M31,RECATALOGANDO!B:C,2,0) -> TRANSFERENCIAS | O31: TRANSFERENCIAS
A32: 44970 | B32: =DAY(A32) -> 13 | C32: =MONTH(A32) -> 2 | D32: =YEAR(A32) -> 2023 | E32: =WEEKDAY(A32,2) -> 1 | F32: =WEEKNUM(A32,2) - WEEKNUM(DATE(YEAR(A32),MONTH(A32),1),2) + 1 -> 3 | H32: 1700 | I32: BANAMEX | J32: TRANSFERENCIA ENTRE CUENTAS | M32: =VLOOKUP(J32,RECATALOGANDO!A:C,2,0) -> TRANSFERENCIA ENTRE CUENTAS | N32: =VLOOKUP(M32,RECATALOGANDO!B:C,2,0) -> TRANSFERENCIAS | O32: TRANSFERENCIAS
A33: 44974 | B33: =DAY(A33) -> 17 | C33: =MONTH(A33) -> 2 | D33: =YEAR(A33) -> 2023 | E33: =WEEKDAY(A33,2) -> 5 | F33: =WEEKNUM(A33,2) - WEEKNUM(DATE(YEAR(A33),MONTH(A33),1),2) + 1 -> 3 | H33: 900 | I33: BBVA | J33: TRANSFERENCIA ENTRE CUENTAS | M33: =VLOOKUP(J33,RECATALOGANDO!A:C,2,0) -> TRANSFERENCIA ENTRE CUENTAS | N33: =VLOOKUP(M33,RECATALOGANDO!B:C,2,0) -> TRANSFERENCIAS | O33: TRANSFERENCIAS
A34: 44974 | B34: =DAY(A34) -> 17 | C34: =MONTH(A34) -> 2 | D34: =YEAR(A34) -> 2023 | E34: =WEEKDAY(A34,2) -> 5 | F34: =WEEKNUM(A34,2) - WEEKNUM(DATE(YEAR(A34),MONTH(A34),1),2) + 1 -> 3 | H34: 900 | I34: BBVA | J34: TRANSFERENCIA ENTRE CUENTAS | M34: =VLOOKUP(J34,RECATALOGANDO!A:C,2,0) -> TRANSFERENCIA ENTRE CUENTAS | N34: =VLOOKUP(M34,RECATALOGANDO!B:C,2,0) -> TRANSFERENCIAS | O34: TRANSFERENCIAS
A35: 44982 | B35: =DAY(A35) -> 25 | C35: =MONTH(A35) -> 2 | D35: =YEAR(A35) -> 2023 | E35: =WEEKDAY(A35,2) -> 6 | F35: =WEEKNUM(A35,2) - WEEKNUM(DATE(YEAR(A35),MONTH(A35),1),2) + 1 -> 4 | H35: 500 | I35: BBVA | J35: TRANSFERENCIA ENTRE CUENTAS | M35: =VLOOKUP(J35,RECATALOGANDO!A:C,2,0) -> TRANSFERENCIA ENTRE CUENTAS | N35: =VLOOKUP(M35,RECATALOGANDO!B:C,2,0) -> TRANSFERENCIAS | O35: TRANSFERENCIAS
A36: 44982 | B36: =DAY(A36) -> 25 | C36: =MONTH(A36) -> 2 | D36: =YEAR(A36) -> 2023 | E36: =WEEKDAY(A36,2) -> 6 | F36: =WEEKNUM(A36,2) - WEEKNUM(DATE(YEAR(A36),MONTH(A36),1),2) + 1 -> 4 | H36: 500 | I36: BBVA | J36: TRANSFERENCIA ENTRE CUENTAS | M36: =VLOOKUP(J36,RECATALOGANDO!A:C,2,0) -> TRANSFERENCIA ENTRE CUENTAS | N36: =VLOOKUP(M36,RECATALOGANDO!B:C,2,0) -> TRANSFERENCIAS | O36: TRANSFERENCIAS
A37: 44988 | B37: =DAY(A37) -> 3 | C37: =MONTH(A37) -> 3 | D37: =YEAR(A37) -> 2023 | E37: =WEEKDAY(A37,2) -> 5 | F37: =WEEKNUM(A37,2) - WEEKNUM(DATE(YEAR(A37),MONTH(A37),1),2) + 1 -> 1 | H37: 800 | I37: BBVA | J37: TRANSFERENCIA ENTRE CUENTAS | M37: =VLOOKUP(J37,RECATALOGANDO!A:C,2,0) -> TRANSFERENCIA ENTRE CUENTAS | N37: =VLOOKUP(M37,RECATALOGANDO!B:C,2,0) -> TRANSFERENCIAS | O37: TRANSFERENCIAS
A38: 44995 | B38: =DAY(A38) -> 10 | C38: =MONTH(A38) -> 3 | D38: =YEAR(A38) -> 2023 | E38: =WEEKDAY(A38,2) -> 5 | F38: =WEEKNUM(A38,2) - WEEKNUM(DATE(YEAR(A38),MONTH(A38),1),2) + 1 -> 2 | H38: 100 | I38: BANAMEX | J38: TRANSFERENCIA ENTRE CUENTAS | M38: =VLOOKUP(J38,RECATALOGANDO!A:C,2,0) -> TRANSFERENCIA ENTRE CUENTAS | N38: =VLOOKUP(M38,RECATALOGANDO!B:C,2,0) -> TRANSFERENCIAS | O38: TRANSFERENCIAS
... A72: 45217 | B72: =DAY(A72) -> 18 | C72: =MONTH(A72) -> 10 | D72: =YEAR(A72) -> 2023 | E72: =WEEKDAY(A72,2) -> 3 | F72: =WEEKNUM(A72,2) - WEEKNUM(DATE(YEAR(A72),MONTH(A72),1),2) + 1 -> 4 | H72: 2100 | I72: BANAMEX | J72: TRANSFERENCIA ENTRE CUENTAS | M72: =VLOOKUP(J72,RECATALOGANDO!A:C,2,0) -> TRANSFERENCIA ENTRE CUENTAS | N72: =VLOOKUP(M72,RECATALOGANDO!B:C,2,0) -> TRANSFERENCIAS | O72: TRANSFERENCIAS
A73: 45229 | B73: =DAY(A73) -> 30 | C73: =MONTH(A73) -> 10 | D73: =YEAR(A73) -> 2023 | E73: =WEEKDAY(A73,2) -> 1 | F73: =WEEKNUM(A73,2) - WEEKNUM(DATE(YEAR(A73),MONTH(A73),1),2) + 1 -> 6 | G73: 2 | H73: 565 | I73: BANAMEX | J73: TRANSFERENCIA ENTRE CUENTAS | M73: =VLOOKUP(J73,RECATALOGANDO!A:C,2,0) -> TRANSFERENCIA ENTRE CUENTAS | N73: =VLOOKUP(M73,RECATALOGANDO!B:C,2,0) -> TRANSFERENCIAS | O73: TRANSFERENCIAS
...

Sheet BASE
A1: FECHA | B1: DIA | C1: MES | D1: ANIO | E1: TIPO_DIA | F1: NUM_SEM | G1: QNA | H1: MONTO | I1: BANCO | J1: CONCEPTO | K1: COMENTARIOS | L1: SALDO ACUM | M1: RECAT | N1: AGRUPACION | O1: INDICE
A2: 45507 | B2: =DAY(A2) -> 3 | C2: =MONTH(A2) -> 8 | D2: =YEAR(A2) -> 2024 | E2: =WEEKDAY(A2,2) -> 6 | F2: =WEEKNUM(A2,2) - WEEKNUM(DATE(YEAR(A2),MONTH(A2),1),2) + 1 -> 1 | H2: 277 | I2: BBVA | M2: NO DATO | N2: NO DATO | O2: NO DATO
A3: 45519 | B3: =DAY(A3) -> 15 | C3: =MONTH(A3) -> 8 | D3: =YEAR(A3) -> 2024 | E3: =WEEKDAY(A3,2) -> 4 | F3: =WEEKNUM(A3,2) - WEEKNUM(DATE(YEAR(A3),MONTH(A3),1),2) + 1 -> 3 | G3: 1 | H3: 729.22 | I3: BBVA | M3: NO DATO | N3: NO DATO | O3: NO DATO
A4: 45522 | B4: =DAY(A4) -> 18 | C4: =MONTH(A4) -> 8 | D4: =YEAR(A4) -> 2024 | E4: =WEEKDAY(A4,2) -> 7 | F4: =WEEKNUM(A4,2) - WEEKNUM(DATE(YEAR(A4),MONTH(A4),1),2) + 1 -> 3 | H4: 1856.11 | I4: BBVA | M4: NO DATO | N4: NO DATO | O4: NO DATO
A5: 45524 | B5: =DAY(A5) -> 20 | C5: =MONTH(A5) -> 8 | D5: =YEAR(A5) -> 2024 | E5: =WEEKDAY(A5,2) -> 2 | F5: =WEEKNUM(A5,2) - WEEKNUM(DATE(YEAR(A5),MONTH(A5),1),2) + 1 -> 4 | H5: 1043.51 | I5: BBVA | M5: NO DATO | N5: NO DATO | O5: NO DATO
A6: 45529 | B6: =DAY(A6) -> 25 | C6: =MONTH(A6) -> 8 | D6: =YEAR(A6) -> 2024 | E6: =WEEKDAY(A6,2) -> 7 | F6: =WEEKNUM(A6,2) - WEEKNUM(DATE(YEAR(A6),MONTH(A6),1),2) + 1 -> 4 | H6: 575.67 | I6: BBVA | M6: NO DATO | N6: NO DATO | O6: NO DATO
A7: 44968 | B7: =DAY(A7) -> 11 | C7: =MONTH(A7) -> 2 | D7: =YEAR(A7) -> 2023 | E7: =WEEKDAY(A7,2) -> 6 | F7: =WEEKNUM(A7,2) - WEEKNUM(DATE(YEAR(A7),MONTH(A7),1),2) + 1 -> 2 | H7: 1815 | I7: BBVA | J7: DONATIVO | M7: =VLOOKUP(J7,RECATALOGANDO!A:C,2,0) -> DONATIVO | N7: =VLOOKUP(M7,RECATALOGANDO!B:C,2,0) -> DONATIVO | O7: NO ES INGRESO
A8: 44968 | B8: =DAY(A8) -> 11 | C8: =MONTH(A8) -> 2 | D8: =YEAR(A8) -> 2023 | E8: =WEEKDAY(A8,2) -> 6 | F8: =WEEKNUM(A8,2) - WEEKNUM(DATE(YEAR(A8),MONTH(A8),1),2) + 1 -> 2 | H8: 1815 | I8: BBVA | J8: DONATIVO | M8: =VLOOKUP(J8,RECATALOGANDO!A:C,2,0) -> DONATIVO | N8: =VLOOKUP(M8,RECATALOGANDO!B:C,2,0) -> DONATIVO | O8: NO ES INGRESO
A9: 45118 | B9: =DAY(A9) -> 11 | C9: =MONTH(A9) -> 7 | D9: =YEAR(A9) -> 2023 | E9: =WEEKDAY(A9,2) -> 2 | F9: =WEEKNUM(A9,2) - WEEKNUM(DATE(YEAR(A9),MONTH(A9),1),2) + 1 -> 3 | H9: 55900 | I9: BBVA | J9: PRESTAMO BANCARIO | M9: =VLOOKUP(J9,RECATALOGANDO!A:C,2,0) -> PRESTAMO BANCARIO | N9: =VLOOKUP(M9,RECATALOGANDO!B:C,2,0) -> PRESTAMO | O9: NO ES INGRESO
A10: 45173 | B10: =DAY(A10) -> 4 | C10: =MONTH(A10) -> 9 | D10: =YEAR(A10) -> 2023 | E10: =WEEKDAY(A10,2) -> 1 | F10: =WEEKNUM(A10,2) - WEEKNUM(DATE(YEAR(A10),MONTH(A10),1),2) + 1 -> 2 | H10: 26571 | I10: BANAMEX | J10: DEPÓSITO EQUIVOCADO Y DEVUELTO | M10: =VLOOKUP(J10,RECATALOGANDO!A:C,2,0) -> REEMBOLSO | N10: =VLOOKUP(M10,RECATALOGANDO!B:C,2,0) -> DINERO DEVUELTO A ORIGEN | O10: NO ES INGRESO
A11: 45181 | B11: =DAY(A11) -> 12 | C11: =MONTH(A11) -> 9 | D11: =YEAR(A11) -> 2023 | E11: =WEEKDAY(A11,2) -> 2 | F11: =WEEKNUM(A11,2) - WEEKNUM(DATE(YEAR(A11),MONTH(A11),1),2) + 1 -> 3 | H11: 80000 | I11: BBVA | J11: DEPÓSITO PRESTAMO | M11: =VLOOKUP(J11,RECATALOGANDO!A:C,2,0) -> DEPÓSITO PRESTAMO | N11: =VLOOKUP(M11,RECATALOGANDO!B:C,2,0) -> PRESTAMO | O11: NO ES INGRESO
A12: 45215 | B12: =DAY(A12) -> 16 | C12: =MONTH(A12) -> 10 | D12: =YEAR(A12) -> 2023 | E12: =WEEKDAY(A12,2) -> 1 | F12: =WEEKNUM(A12,2) - WEEKNUM(DATE(YEAR(A12),MONTH(A12),1),2) + 1 -> 4 | H12: 200 | I12: BANAMEX | J12: REEMBOLSO | M12: =VLOOKUP(J12,RECATALOGANDO!A:C,2,0) -> REEMBOLSO | N12: =VLOOKUP(M12,RECATALOGANDO!B:C,2,0) -> DINERO DEVUELTO A ORIGEN | O12: NO ES INGRESO
A13: 45282 | B13: =DAY(A13) -> 22 | C13: =MONTH(A13) -> 12 | D13: =YEAR(A13) -> 2023 | E13: =WEEKDAY(A13,2) -> 5 | F13: =WEEKNUM(A13,2) - WEEKNUM(DATE(YEAR(A13),MONTH(A13),1),2) + 1 -> 4 | H13: 2895 | I13: BBVA | J13: REEMBOLSO POR DEPOSITO EQUIVOCADO | M13: =VLOOKUP(J13,RECATALOGANDO!A:C,2,0) -> REEMBOLSO | N13: =VLOOKUP(M13,RECATALOGANDO!B:C,2,0) -> DINERO DEVUELTO A ORIGEN | O13: NO ES INGRESO
A14: 45365 | B14: =DAY(A14) -> 14 | C14: =MONTH(A14) -> 3 | D14: =YEAR(A14) -> 2024 | E14: =WEEKDAY(A14,2) -> 4 | F14: =WEEKNUM(A14,2) - WEEKNUM(DATE(YEAR(A14),MONTH(A14),1),2) + 1 -> 3 | H14: 3500 | I14: BBVA | J14: REEMBOLSO | M14: =VLOOKUP(J14,RECATALOGANDO!A:C,2,0) -> REEMBOLSO | N14: =VLOOKUP(M14,RECATALOGANDO!B:C,2,0) -> DINERO DEVUELTO A ORIGEN | O14: NO ES INGRESO
A15: 45366 | B15: =DAY(A15) -> 15 | C15: =MONTH(A15) -> 3 | D15: =YEAR(A15) -> 2024 | E15: =WEEKDAY(A15,2) -> 5 | F15: =WEEKNUM(A15,2) - WEEKNUM(DATE(YEAR(A15),MONTH(A15),1),2) + 1 -> 3 | G15: 1 | H15: 140 | I15: BANAMEX | J15: REEMBOLSO | M15: =VLOOKUP(J15,RECATALOGANDO!A:C,2,0) -> REEMBOLSO | N15: =VLOOKUP(M15,RECATALOGANDO!B:C,2,0) -> DINERO DEVUELTO A ORIGEN | O15: NO ES INGRESO
A16: 45527 | B16: =DAY(A16) -> 23 | C16: =MONTH(A16) -> 8 | D16: =YEAR(A16) -> 2024 | E16: =WEEKDAY(A16,2) -> 5 | F16: =WEEKNUM(A16,2) - WEEKNUM(DATE(YEAR(A16),MONTH(A16),1),2) + 1 -> 4 | H16: 5000 | I16: BANAMEX | J16: PENSIÓN ALIMENTICIA | M16: =VLOOKUP(J16,RECATALOGANDO!A:C,2,0) -> PENSION ALIMENTICIA | N16: =VLOOKUP(M16,RECATALOGANDO!B:C,2,0) -> PENSION | O16: NO ES INGRESO
A17: 45587 | B17: =DAY(A17) -> 22 | C17: =MONTH(A17) -> 10 | D17: =YEAR(A17) -> 2024 | E17: =WEEKDAY(A17,2) -> 2 | F17: =WEEKNUM(A17,2) - WEEKNUM(DATE(YEAR(A17),MONTH(A17),1),2) + 1 -> 4 | H17: 7800 | I17: BANAMEX | J17: DEPOSITO EQUIVOCADO QUE FUE REEMBOLSADO | M17: =VLOOKUP(J17,RECATALOGANDO!A:C,2,0) -> REEMBOLSO | N17: =VLOOKUP(M17,RECATALOGANDO!B:C,2,0) -> DINERO DEVUELTO A ORIGEN | O17: NO ES INGRESO
A18: 45589 | B18: =DAY(A18) -> 24 | C18: =MONTH(A18) -> 10 | D18: =YEAR(A18) -> 2024 | E18: =WEEKDAY(A18,2) -> 4 | F18: =WEEKNUM(A18,2) - WEEKNUM(DATE(YEAR(A18),MONTH(A18),1),2) + 1 -> 4 | H18: 1340 | I18: BANAMEX | J18: DEVOLUCIÓN SPEI | M18: =VLOOKUP(J18,RECATALOGANDO!A:C,2,0) -> REEMBOLSO | N18: =VLOOKUP(M18,RECATALOGANDO!B:C,2,0) -> DINERO DEVUELTO A ORIGEN | O18: NO ES INGRESO
A19: 45602 | B19: =DAY(A19) -> 6 | C19: =MONTH(A19) -> 11 | D19: =YEAR(A19) -> 2024 | E19: =WEEKDAY(A19,2) -> 3 | F19: =WEEKNUM(A19,2) - WEEKNUM(DATE(YEAR(A19),MONTH(A19),1),2) + 1 -> 2 | H19: 226309.64 | I19: BBVA | J19: DEPOSITO PENSION ALIMENTICIA | M19: =VLOOKUP(J19,RECATALOGANDO!A:C,2,0) -> PENSION ALIMENTICIA | N19: =VLOOKUP(M19,RECATALOGANDO!B:C,2,0) -> PENSION | O19: NO ES INGRESO
A20: 45693 | B20: =DAY(A20) -> 5 | C20: =MONTH(A20) -> 2 | D20: =YEAR(A20) -> 2025 | E20: =WEEKDAY(A20,2) -> 3 | F20: =WEEKNUM(A20,2) - WEEKNUM(DATE(YEAR(A20),MONTH(A20),1),2) + 1 -> 2 | H20: 676.46 | I20: BANAMEX | J20: ABONO POR REEMBOLSO POR CARGO NO RECONOCIDO | M20: =VLOOKUP(J20,RECATALOGANDO!A:C,2,0) -> REEMBOLSO | N20: =VLOOKUP(M20,RECATALOGANDO!B:C,2,0) -> DINERO DEVUELTO A ORIGEN | O20: NO ES INGRESO
A21: 45695 | B21: =DAY(A21) -> 7 | C21: =MONTH(A21) -> 2 | D21: =YEAR(A21) -> 2025 | E21: =WEEKDAY(A21,2) -> 5 | F21: =WEEKNUM(A21,2) - WEEKNUM(DATE(YEAR(A21),MONTH(A21),1),2) + 1 -> 2 | H21: 676.46 | I21: BANAMEX | J21: ABONO POR REEMBOLSO POR CARGO NO RECONOCIDO | M21: =VLOOKUP(J21,RECATALOGANDO!A:C,2,0) -> REEMBOLSO | N21: =VLOOKUP(M21,RECATALOGANDO!B:C,2,0) -> DINERO DEVUELTO A ORIGEN | O21: NO ES INGRESO
A22: 45698 | B22: =DAY(A22) -> 10 | C22: =MONTH(A22) -> 2 | D22: =YEAR(A22) -> 2025 | E22: =WEEKDAY(A22,2) -> 1 | F22: =WEEKNUM(A22,2) - WEEKNUM(DATE(YEAR(A22),MONTH(A22),1),2) + 1 -> 3 | H22: 676.46 | I22: BANAMEX | J22: ABONO POR REEMBOLSO POR CARGO NO RECONOCIDO | M22: =VLOOKUP(J22,RECATALOGANDO!A:C,2,0) -> REEMBOLSO | N22: =VLOOKUP(M22,RECATALOGANDO!B:C,2,0) -> DINERO DEVUELTO A ORIGEN | O22: NO ES INGRESO
A23: 44930 | B23: =DAY(A23) -> 4 | C23: =MONTH(A23) -> 1 | D23: =YEAR(A23) -> 2023 | E23: =WEEKDAY(A23,2) -> 3 | F23: =WEEKNUM(A23,2) - WEEKNUM(DATE(YEAR(A23),MONTH(A23),1),2) + 1 -> 2 | H23: 1000 | I23: BANAMEX | J23: TRANFERENCIA ENTRE CUENTAS | M23: =VLOOKUP(J23,RECATALOGANDO!A:C,2,0) -> TRANSFERENCIA ENTRE CUENTAS | N23: =VLOOKUP(M23,RECATALOGANDO!B:C,2,0) -> TRANSFERENCIAS | O23: TRANSFERENCIAS
A24: 44941 | B24: =DAY(A24) -> 15 | C24: =MONTH(A24) -> 1 | D24: =YEAR(A24) -> 2023 | E24: =WEEKDAY(A24,2) -> 7 | F24: =WEEKNUM(A24,2) - WEEKNUM(DATE(YEAR(A24),MONTH(A24),1),2) + 1 -> 3 | H24: 200 | I24: BBVA | J24: TRANFERENCIA ENTRE CUENTAS | M24: =VLOOKUP(J24,RECATALOGANDO!A:C,2,0) -> TRANSFERENCIA ENTRE CUENTAS | N24: =VLOOKUP(M24,RECATALOGANDO!B:C,2,0) -> TRANSFERENCIAS | O24: TRANSFERENCIAS
A25: 44956 | B25: =DAY(A25) -> 30 | C25: =MONTH(A25) -> 1 | D25: =YEAR(A25) -> 2023 | E25: =WEEKDAY(A25,2) -> 1 | F25: =WEEKNUM(A25,2) - WEEKNUM(DATE(YEAR(A25),MONTH(A25),1),2) + 1 -> 6 | G25: 2 | H25: 700 | I25: BBVA | J25: TRANSFERENCIA ENTRE CUENTAS | M25: =VLOOKUP(J25,RECATALOGANDO!A:C,2,0) -> TRANSFERENCIA ENTRE CUENTAS | N25: =VLOOKUP(M25,RECATALOGANDO!B:C,2,0) -> TRANSFERENCIAS | O25: TRANSFERENCIAS
A26: 44956 | B26: =DAY(A26) -> 30 | C26: =MONTH(A26) -> 1 | D26: =YEAR(A26) -> 2023 | E26: =WEEKDAY(A26,2) -> 1 | F26: =WEEKNUM(A26,2) - WEEKNUM(DATE(YEAR(A26),MONTH(A26),1),2) + 1 -> 6 | G26: 2 | H26: 700 | I26: BBVA | J26: TRANSFERENCIA ENTRE CUENTAS | M26: =VLOOKUP(J26,RECATALOGANDO!A:C,2,0) -> TRANSFERENCIA ENTRE CUENTAS | N26: =VLOOKUP(M26,RECATALOGANDO!B:C,2,0) -> TRANSFERENCIAS | O26: TRANSFERENCIAS
A27: 44958 | B27: =DAY(A27) -> 1 | C27: =MONTH(A27) -> 2 | D27: =YEAR(A27) -> 2023 | E27: =WEEKDAY(A27,2) -> 3 | F27: =WEEKNUM(A27,2) - WEEKNUM(DATE(YEAR(A27),MONTH(A27),1),2) + 1 -> 1 | H27: 1000 | I27: BANAMEX | J27: TRANSFERENCIA ENTRE CUENTAS | M27: =VLOOKUP(J27,RECATALOGANDO!A:C,2,0) -> TRANSFERENCIA ENTRE CUENTAS | N27: =VLOOKUP(M27,RECATALOGANDO!B:C,2,0) -> TRANSFERENCIAS | O27: TRANSFERENCIAS
A28: 44958 | B28: =DAY(A28) -> 1 | C28: =MONTH(A28) -> 2 | D28: =YEAR(A28) -> 2023 | E28: =WEEKDAY(A28,2) -> 3 | F28: =WEEKNUM(A28,2) - WEEKNUM(DATE(YEAR(A28),MONTH(A28),1),2) + 1 -> 1 | H28: 1000 | I28: BANAMEX | J28: TRANSFERENCIA ENTRE CUENTAS | M28: =VLOOKUP(J28,RECATALOGANDO!A:C,2,0) -> TRANSFERENCIA ENTRE CUENTAS | N28: =VLOOKUP(M28,RECATALOGANDO!B:C,2,0) -> TRANSFERENCIAS | O28: TRANSFERENCIAS
A29: 44965 | B29: =DAY(A29) -> 8 | C29: =MONTH(A29) -> 2 | D29: =YEAR(A29) -> 2023 | E29: =WEEKDAY(A29,2) -> 3 | F29: =WEEKNUM(A29,2) - WEEKNUM(DATE(YEAR(A29),MONTH(A29),1),2) + 1 -> 2 | H29: 500 | I29: BANAMEX | J29: TRANSFERENCIA ENTRE CUENTAS | M29: =VLOOKUP(J29,RECATALOGANDO!A:C,2,0) -> TRANSFERENCIA ENTRE CUENTAS | N29: =VLOOKUP(M29,RECATALOGANDO!B:C,2,0) -> TRANSFERENCIAS | O29: TRANSFERENCIAS
A30: 44965 | B30: =DAY(A30) -> 8 | C30: =MONTH(A30) -> 2 | D30: =YEAR(A30) -> 2023 | E30: =WEEKDAY(A30,2) -> 3 | F30: =WEEKNUM(A30,2) - WEEKNUM(DATE(YEAR(A30),MONTH(A30),1),2) + 1 -> 2 | H30: 500 | I30: BANAMEX | J30: TRANSFERENCIA ENTRE CUENTAS | M30: =VLOOKUP(J30,RECATALOGANDO!A:C,2,0) -> TRANSFERENCIA ENTRE CUENTAS | N30: =VLOOKUP(M30,RECATALOGANDO!B:C,2,0) -> TRANSFERENCIAS | O30: TRANSFERENCIAS
A31: 44970 | B31: =DAY(A31) -> 13 | C31: =MONTH(A31) -> 2 | D31: =YEAR(A31) -> 2023 | E31: =WEEKDAY(A31,2) -> 1 | F31: =WEEKNUM(A31,2) - WEEKNUM(DATE(YEAR(A31),MONTH(A31),1),2) + 1 -> 3 | H31: 1700 | I31: BANAMEX | J31: TRANSFERENCIA ENTRE CUENTAS | M31: =VLOOKUP(J31,RECATALOGANDO!A:C,2,0) -> TRANSFERENCIA ENTRE CUENTAS | N31: =VLOOKUP(M31,RECATALOGANDO!B:C,2,0) -> TRANSFERENCIAS | O31: TRANSFERENCIAS
A32: 44970 | B32: =DAY(A32) -> 13 | C32: =MONTH(A32) -> 2 | D32: =YEAR(A32) -> 2023 | E32: =WEEKDAY(A32,2) -> 1 | F32: =WEEKNUM(A32,2) - WEEKNUM(DATE(YEAR(A32),MONTH(A32),1),2) + 1 -> 3 | H32: 1700 | I32: BANAMEX | J32: TRANSFERENCIA ENTRE CUENTAS | M32: =VLOOKUP(J32,RECATALOGANDO!A:C,2,0) -> TRANSFERENCIA ENTRE CUENTAS | N32: =VLOOKUP(M32,RECATALOGANDO!B:C,2,0) -> TRANSFERENCIAS | O32: TRANSFERENCIAS
A33: 44974 | B33: =DAY(A33) -> 17 | C33: =MONTH(A33) -> 2 | D33: =YEAR(A33) -> 2023 | E33: =WEEKDAY(A33,2) -> 5 | F33: =WEEKNUM(A33,2) - WEEKNUM(DATE(YEAR(A33),MONTH(A33),1),2) + 1 -> 3 | H33: 900 | I33: BBVA | J33: TRANSFERENCIA ENTRE CUENTAS | M33: =VLOOKUP(J33,RECATALOGANDO!A:C,2,0) -> TRANSFERENCIA ENTRE CUENTAS | N33: =VLOOKUP(M33,RECATALOGANDO!B:C,2,0) -> TRANSFERENCIAS | O33: TRANSFERENCIAS
A34: 44974 | B34: =DAY(A34) -> 17 | C34: =MONTH(A34) -> 2 | D34: =YEAR(A34) -> 2023 | E34: =WEEKDAY(A34,2) -> 5 | F34: =WEEKNUM(A34,2) - WEEKNUM(DATE(YEAR(A34),MONTH(A34),1),2) + 1 -> 3 | H34: 900 | I34: BBVA | J34: TRANSFERENCIA ENTRE CUENTAS | M34: =VLOOKUP(J34,RECATALOGANDO!A:C,2,0) -> TRANSFERENCIA ENTRE CUENTAS | N34: =VLOOKUP(M34,RECATALOGANDO!B:C,2,0) -> TRANSFERENCIAS | O34: TRANSFERENCIAS
A35: 44982 | B35: =DAY(A35) -> 25 | C35: =MONTH(A35) -> 2 | D35: =YEAR(A35) -> 2023 | E35: =WEEKDAY(A35,2) -> 6 | F35: =WEEKNUM(A35,2) - WEEKNUM(DATE(YEAR(A35),MONTH(A35),1),2) + 1 -> 4 | H35: 500 | I35: BBVA | J35: TRANSFERENCIA ENTRE CUENTAS | M35: =VLOOKUP(J35,RECATALOGANDO!A:C,2,0) -> TRANSFERENCIA ENTRE CUENTAS | N35: =VLOOKUP(M35,RECATALOGANDO!B:C,2,0) -> TRANSFERENCIAS | O35: TRANSFERENCIAS
A36: 44982 | B36: =DAY(A36) -> 25 | C36: =MONTH(A36) -> 2 | D36: =YEAR(A36) -> 2023 | E36: =WEEKDAY(A36,2) -> 6 | F36: =WEEKNUM(A36,2) - WEEKNUM(DATE(YEAR(A36),MONTH(A36),1),2) + 1 -> 4 | H36: 500 | I36: BBVA | J36: TRANSFERENCIA ENTRE CUENTAS | M36: =VLOOKUP(J36,RECATALOGANDO!A:C,2,0) -> TRANSFERENCIA ENTRE CUENTAS | N36: =VLOOKUP(M36,RECATALOGANDO!B:C,2,0) -> TRANSFERENCIAS | O36: TRANSFERENCIAS
A37: 44988 | B37: =DAY(A37) -> 3 | C37: =MONTH(A37) -> 3 | D37: =YEAR(A37) -> 2023 | E37: =WEEKDAY(A37,2) -> 5 | F37: =WEEKNUM(A37,2) - WEEKNUM(DATE(YEAR(A37),MONTH(A37),1),2) + 1 -> 1 | H37: 800 | I37: BBVA | J37: TRANSFERENCIA ENTRE CUENTAS | M37: =VLOOKUP(J37,RECATALOGANDO!A:C,2,0) -> TRANSFERENCIA ENTRE CUENTAS | N37: =VLOOKUP(M37,RECATALOGANDO!B:C,2,0) -> TRANSFERENCIAS | O37: TRANSFERENCIAS
A38: 44995 | B38: =DAY(A38) -> 10 | C38: =MONTH(A38) -> 3 | D38: =YEAR(A38) -> 2023 | E38: =WEEKDAY(A38,2) -> 5 | F38: =WEEKNUM(A38,2) - WEEKNUM(DATE(YEAR(A38),MONTH(A38),1),2) + 1 -> 2 | H38: 100 | I38: BANAMEX | J38: TRANSFERENCIA ENTRE CUENTAS | M38: =VLOOKUP(J38,RECATALOGANDO!A:C,2,0) -> TRANSFERENCIA ENTRE CUENTAS | N38: =VLOOKUP(M38,RECATALOGANDO!B:C,2,0) -> TRANSFERENCIAS | O38: TRANSFERENCIAS
... A72: 45217 | B72: =DAY(A72) -> 18 | C72: =MONTH(A72) -> 10 | D72: =YEAR(A72) -> 2023 | E72: =WEEKDAY(A72,2) -> 3 | F72: =WEEKNUM(A72,2) - WEEKNUM(DATE(YEAR(A72),MONTH(A72),1),2) + 1 -> 4 | H72: 2100 | I72: BANAMEX | J72: TRANSFERENCIA ENTRE CUENTAS | M72: =VLOOKUP(J72,RECATALOGANDO!A:C,2,0) -> TRANSFERENCIA ENTRE CUENTAS | N72: =VLOOKUP(M72,RECATALOGANDO!B:C,2,0) -> TRANSFERENCIAS | O72: TRANSFERENCIAS
A73: 45229 | B73: =DAY(A73) -> 30 | C73: =MONTH(A73) -> 10 | D73: =YEAR(A73) -> 2023 | E73: =WEEKDAY(A73,2) -> 1 | F73: =WEEKNUM(A73,2) - WEEKNUM(DATE(YEAR(A73),MONTH(A73),1),2) + 1 -> 6 | G73: 2 | H73: 565 | I73: BANAMEX | J73: TRANSFERENCIA ENTRE CUENTAS | M73: =VLOOKUP(J73,RECATALOGANDO!A:C,2,0) -> TRANSFERENCIA ENTRE CUENTAS | N73: =VLOOKUP(M73,RECATALOGANDO!B:C,2,0) -> TRANSFERENCIAS | O73: TRANSFERENCIAS
...

Sheet RECATALOGANDO
A1: CONCEPTO | B1: CONCEPTO 2 | C1: AGRUPADO | H1: CONCEPTO 2 | I1: AGRUPADO
A2: ABONO POR REEMBOLSO POR CARGO NO RECONOCIDO | B2: REEMBOLSO | C2: DINERO DEVUELTO A ORIGEN | H2: REEMBOLSO | I2: DINERO DEVUELTO A ORIGEN
A3: APLICACIÓN DE VACUNAS | B3: VENTA DE MEDICAMENTO | C3: VENTA DE PRODUCTO | H3: VENTA DE MEDICAMENTO | I3: VENTA DE PRODUCTO
A4: DEPOSITO EQUIVOCADO QUE FUE REEMBOLSADO | B4: REEMBOLSO | C4: DINERO DEVUELTO A ORIGEN | H4: TRANSFERENCIA FAMILIAR | I4: TRANSFERENCIAS
A5: DEPÓSITO EQUIVOCADO Y DEVUELTO | B5: REEMBOLSO | C5: DINERO DEVUELTO A ORIGEN | H5: PENSION ALIMENTICIA | I5: PENSION
A6: DEPOSITO FAMILIAR | B6: TRANSFERENCIA FAMILIAR | C6: TRANSFERENCIAS | H6: DEPÓSITO PRESTAMO | I6: PRESTAMO
A7: DEPÓSITO FAMILIAR | B7: TRANSFERENCIA FAMILIAR | C7: TRANSFERENCIAS | H7: REEMBOLSO | I7: DINERO DEVUELTO
A8: DEPOSITO PENSION ALIMENTICIA | B8: PENSION ALIMENTICIA | C8: PENSION | H8: DONATIVO | I8: DONATIVO
A9: DEPÓSITO PRESTAMO | B9: DEPÓSITO PRESTAMO | C9: PRESTAMO | H9: TRANSFERENCIA ENTRE CUENTAS | I9: TRANSFERENCIAS
A10: DEVOLUCIÓN SPEI | B10: REEMBOLSO | C10: DINERO DEVUELTO | H10: HONORARIOS MEDICOS | I10: VENTA DE SERVICIO
A11: DONATIVO | B11: DONATIVO | C11: DONATIVO | H11: HONORARIOS QUIRURGICOS | I11: VENTA DE SERVICIO
A12: ENTRE CUENTAS | B12: TRANSFERENCIA ENTRE CUENTAS | C12: TRANSFERENCIAS | H12: VENTA DE ALIMENTO | I12: VENTA DE PRODUCTO
... A20: PAGO SERVICIO DE PENSIÓN | B20: SERVICIO DE PENSION | C20: VENTA DE SERVICIO | H20: VENTA DE ACCESORIOS | I20: VENTA DE PRODUCTO
A21: PENSIÓN ALIMENTICIA | B21: PENSION ALIMENTICIA | C21: PENSION
A22: PRESTAMO BANCARIO | B22: PRESTAMO BANCARIO | C22: PRESTAMO
A23: REEMBOLSO | B23: REEMBOLSO | C23: DINERO DEVUELTO A ORIGEN
A24: REEMBOLSO POR DEPOSITO EQUIVOCADO | B24: REEMBOLSO | C24: DINERO DEVUELTO A ORIGEN
A25: SERVCIO DE PENSIÓN | B25: SERVICIO DE PENSION | C25: VENTA DE SERVICIO
A26: SERVICIO DE CREMACIÓN | B26: SERVICIO DE CREMACION | C26: VENTA DE SERVICIO
A27: SERVICIO DE GROOMING | B27: SERVICIO DE GROOMING | C27: VENTA DE SERVICIO
A28: SERVICIO DE HOSPITALIZACION | B28: SERVICIO DE HOSPITALIZACION | C28: VENTA DE SERVICIO
A29: SERVICIO DE IMAGEN | B29: SERVICIO DE IMAGEN | C29: VENTA DE SERVICIO
A30: SERVICIO DE IMAGENOLOGIA | B30: SERVICIO DE IMAGEN | C30: VENTA DE SERVICIO
A31: SERVICIO DE INCINERACIÓN | B31: SERVICIO DE CREMACION | C31: VENTA DE SERVICIO
A32: SERVICIO DE LABORATORIO | B32: SERVICIO DE LABORATORIO | C32: VENTA DE SERVICIO
... A56: VENTA MEDICAMENTO | B56: VENTA DE MEDICAMENTO | C56: VENTA DE PRODUCTO

Sheet CATS
A1: ID | B1: DESCRIPCION | F1: ID_ | G1: DESCRIPCION | I1: ID | J1: DESCRIPCION
A2: 1 | B2: HONORARIOS MEDICOS | C2: MEDICOS | F2: 1 | G2: BBVA | I2: 1 | J2: VENTAS
A3: 2 | B3: HONORARIOS QUIRURGICOS | C3: QUIRURGICOS | F3: 2 | G3: BANAMEX | I3: 2 | J3: TRANSFERENCIA
A4: 3 | B4: SERVICIO DE CREMACIÓN | C4: CREMACIÓN | F4: 3 | G4: BANORTE | I4: 3 | J4: HONORARIOS
A5: 4 | B5: SERVICIO DE GROOMING | C5: GROOMING | I5: 4 | J5: SERVICIOS
A6: 5 | B6: SERVICIO DE LABORATORIO | C6: LABORATORIO
A7: 6 | B7: SERVICIO DE PENSIÓN | C7: PENSIÓN
A8: 7 | B8: TRANSFERENCIA ENTRE CUENTAS | C8: CUENTAS
A9: 8 | B9: TRANSFERENCIA FAMILIARES | C9: FAMILIARES
A10: 9 | B10: VENTA DE ALIMENTO | C10: ALIMENTO
A11: 10 | B11: VENTA DE MEDICAMENTO | C11: MEDICAMENTO
